src/__tests__/bitmexObRaw.json
[{"action":"partial","ts":"2020-03-13T12:20:31.302Z","data":[{"id":8799455000,"side":"Sell","size":4624,"price":5450},{"id":8799455100,"side":"Sell","size":1000,"price":5449},{"id":8799455150,"side":"Sell","size":280,"price":5448.5},{"id":8799455200,"side":"Sell","size":20612,"price":5448},{"id":8799455250,"side":"Sell","size":201,"price":5447.5},{"id":8799455300,"side":"Sell","size":2,"price":5447},{"id":8799455400,"side":"Sell","size":1,"price":5446},{"id":8799455500,"side":"Sell","size":6505,"price":5445},{"id":8799455550,"side":"Sell","size":100,"price":5444.5},{"id":8799455600,"side":"Sell","size":947,"price":5444},{"id":8799455800,"side":"Sell","size":16,"price":5442},{"id":8799455900,"side":"Sell","size":5569,"price":5441},{"id":8799457950,"side":"Sell","size":400,"price":5420.5},{"id":8799460000,"side":"Sell","size":2700,"price":5400},{"id":8799460100,"side":"Sell","size":250,"price":5399},{"id":8799460500,"side":"Sell","size":90,"price":5395},{"id":8799460700,"side":"Sell","size":201,"price":5393},{"id":8799462000,"side":"Sell","size":11400,"price":5380},{"id":8799462500,"side":"Sell","size":6,"price":5375},{"id":8799463400,"side":"Sell","size":20000,"price":5366},{"id":8799464800,"side":"Sell","size":50,"price":5352},{"id":8799465000,"side":"Sell","size":80000,"price":5350},{"id":8799465500,"side":"Sell","size":46750,"price":5345},{"id":8799470000,"side":"Sell","size":17000,"price":5300},{"id":8799470200,"side":"Sell","size":9624404,"price":5298},{"id":8799477850,"side":"Buy","size":1246,"price":5221.5},{"id":8799483000,"side":"Buy","size":5000,"price":5170},{"id":8799483500,"side":"Buy","size":39405,"price":5165},{"id":8799483550,"side":"Buy","size":8630,"price":5164.5},{"id":8799483600,"side":"Buy","size":65,"price":5164},{"id":8799483700,"side":"Buy","size":3033,"price":5163},{"id":8799483750,"side":"Buy","size":40,"price":5162.5},{"id":8799483800,"side":"Buy","size":14040,"price":5162},{"id":8799483900,"side":"Buy","size":24969,"price":5161},{"id":8799483950,"side":"Buy","size":50000,"price":5160.5},{"id":8799484000,"side":"Buy","size":121152,"price":5160},{"id":8799484100,"side":"Buy","size":2500,"price":5159},{"id":8799484150,"side":"Buy","size":1112,"price":5158.5},{"id":8799484250,"side":"Buy","size":500,"price":5157.5},{"id":8799484300,"side":"Buy","size":800,"price":5157},{"id":8799484400,"side":"Buy","size":8050,"price":5156},{"id":8799484450,"side":"Buy","size":10050,"price":5155.5},{"id":8799484500,"side":"Buy","size":7444,"price":5155},{"id":8799484550,"side":"Buy","size":2025,"price":5154.5},{"id":8799484600,"side":"Buy","size":384,"price":5154},{"id":8799484650,"side":"Buy","size":3000,"price":5153.5},{"id":8799484700,"side":"Buy","size":1050,"price":5153},{"id":8799484800,"side":"Buy","size":700,"price":5152},{"id":8799484850,"side":"Buy","size":4450,"price":5151.5},{"id":8799484900,"side":"Buy","size":130568,"price":5151}],"i":0},{"action":"delete","ts":"2020-03-13T12:20:31.378Z","data":[{"id":8799484900,"side":"Buy"}],"i":1},{"action":"update","ts":"2020-03-13T12:20:31.381Z","data":[{"id":8799455000,"side":"Sell","size":4604}],"i":2},{"action":"insert","ts":"2020-03-13T12:20:31.382Z","data":[{"id":8799482450,"side":"Buy","size":1000,"price":5175.5}],"i":3},{"action":"delete","ts":"2020-03-13T12:20:31.404Z","data":[{"id":8799484800,"side":"Buy"},{"id":8799484850,"side":"Buy"}],"i":4},{"action":"update","ts":"2020-03-13T12:20:31.405Z","data":[{"id":8799455600,"side":"Sell","size":972},{"id":8799470200,"side":"Sell","size":9654404},{"id":8799477850,"side":"Buy","size":53246}],"i":5},{"action":"insert","ts":"2020-03-13T12:20:31.405Z","data":[{"id":8799478050,"side":"Buy","size":1525,"price":5219.5},{"id":8799480000,"side":"Buy","size":4000,"price":5200}],"i":6},{"action":"update","ts":"2020-03-13T12:20:31.431Z","data":[{"id":8799470200,"side":"Sell","size":9632384}],"i":7},{"action":"update","ts":"2020-03-13T12:20:31.563Z","data":[{"id":8799470200,"side":"Sell","size":9628937}],"i":8},{"action":"update","ts":"2020-03-13T12:20:31.657Z","data":[{"id":8799477850,"side":"Buy","size":93246},{"id":8799483000,"side":"Buy","size":10170}],"i":9},{"action":"delete","ts":"2020-03-13T12:20:31.756Z","data":[{"id":8799484600,"side":"Buy"},{"id":8799484650,"side":"Buy"},{"id":8799484700,"side":"Buy"}],"i":10},{"action":"update","ts":"2020-03-13T12:20:31.758Z","data":[{"id":8799470200,"side":"Sell","size":9257216}],"i":11},{"action":"insert","ts":"2020-03-13T12:20:31.764Z","data":[{"id":8799471800,"side":"Buy","size":12,"price":5282},{"id":8799473700,"side":"Buy","size":20000,"price":5263},{"id":8799477750,"side":"Buy","size":427,"price":5222.5}],"i":12},{"action":"update","ts":"2020-03-13T12:20:31.855Z","data":[{"id":8799470200,"side":"Sell","size":9257215}],"i":13},{"action":"delete","ts":"2020-03-13T12:20:32.055Z","data":[{"id":8799473700,"side":"Buy"}],"i":14},{"action":"update","ts":"2020-03-13T12:20:32.057Z","data":[{"id":8799471800,"side":"Buy","size":11}],"i":15},{"action":"insert","ts":"2020-03-13T12:20:32.059Z","data":[{"id":8799472100,"side":"Buy","size":20000,"price":5279}],"i":16},{"action":"update","ts":"2020-03-13T12:20:32.156Z","data":[{"id":8799470200,"side":"Sell","size":9257214},{"id":8799471800,"side":"Buy","size":52011},{"id":8799477850,"side":"Buy","size":41246}],"i":17},{"action":"update","ts":"2020-03-13T12:20:32.255Z","data":[{"id":8799471800,"side":"Buy","size":52010}],"i":18},{"action":"update","ts":"2020-03-13T12:20:32.454Z","data":[{"id":8799470200,"side":"Sell","size":9257213}],"i":19},{"action":"update","ts":"2020-03-13T12:20:33.512Z","data":[{"id":8799471800,"side":"Buy","size":52009}],"i":20},{"action":"update","ts":"2020-03-13T12:20:33.541Z","data":[{"id":8799470200,"side":"Sell","size":9257212},{"id":8799471800,"side":"Buy","size":92009},{"id":8799477850,"side":"Buy","size":1246}],"i":21},{"action":"update","ts":"2020-03-13T12:20:33.562Z","data":[{"id":8799470200,"side":"Sell","size":9257187}],"i":22},{"action":"update","ts":"2020-03-13T12:20:33.564Z","data":[{"id":8799471800,"side":"Buy","size":92008}],"i":23},{"action":"update","ts":"2020-03-13T12:20:33.572Z","data":[{"id":8799470200,"side":"Sell","size":9257186}],"i":24}]
