src/__tests__/bybitObRaw.json
[{"type":"snapshot","ts":"2020-03-02T06:00:00.000Z","v":1,"data":[{"price":"6881.00","symbol":"BTCUSD","id":68810000,"side":"Buy","size":28571},{"price":"8646.50","symbol":"BTCUSD","id":86465000,"side":"Buy","size":51612},{"price":"8647.50","symbol":"BTCUSD","id":86475000,"side":"Buy","size":89206},{"price":"8648.00","symbol":"BTCUSD","id":86480000,"side":"Buy","size":55155},{"price":"8649.00","symbol":"BTCUSD","id":86490000,"side":"Buy","size":74630},{"price":"8650.50","symbol":"BTCUSD","id":86505000,"side":"Buy","size":51789},{"price":"8652.50","symbol":"BTCUSD","id":86525000,"side":"Buy","size":183691},{"price":"8653.00","symbol":"BTCUSD","id":86530000,"side":"Buy","size":77027},{"price":"8653.50","symbol":"BTCUSD","id":86535000,"side":"Buy","size":19805},{"price":"8654.00","symbol":"BTCUSD","id":86540000,"side":"Buy","size":91043},{"price":"8654.50","symbol":"BTCUSD","id":86545000,"side":"Buy","size":157544},{"price":"8655.00","symbol":"BTCUSD","id":86550000,"side":"Buy","size":75000},{"price":"8655.50","symbol":"BTCUSD","id":86555000,"side":"Buy","size":148759},{"price":"8657.00","symbol":"BTCUSD","id":86570000,"side":"Buy","size":256389},{"price":"8659.00","symbol":"BTCUSD","id":86590000,"side":"Sell","size":355988},{"price":"8659.50","symbol":"BTCUSD","id":86595000,"side":"Sell","size":270613},{"price":"8660.00","symbol":"BTCUSD","id":86600000,"side":"Sell","size":721148},{"price":"8660.50","symbol":"BTCUSD","id":86605000,"side":"Sell","size":318841},{"price":"8661.00","symbol":"BTCUSD","id":86610000,"side":"Sell","size":360994},{"price":"8661.50","symbol":"BTCUSD","id":86615000,"side":"Sell","size":241568},{"price":"8662.00","symbol":"BTCUSD","id":86620000,"side":"Sell","size":278726},{"price":"8662.50","symbol":"BTCUSD","id":86625000,"side":"Sell","size":144555},{"price":"8663.00","symbol":"BTCUSD","id":86630000,"side":"Sell","size":91315},{"price":"8663.50","symbol":"BTCUSD","id":86635000,"side":"Sell","size":121103},{"price":"8664.00","symbol":"BTCUSD","id":86640000,"side":"Sell","size":209912},{"price":"8664.50","symbol":"BTCUSD","id":86645000,"side":"Sell","size":93209},{"price":"8665.00","symbol":"BTCUSD","id":86650000,"side":"Sell","size":97746},{"price":"8665.50","symbol":"BTCUSD","id":86655000,"side":"Sell","size":193872},{"price":"8666.00","symbol":"BTCUSD","id":86660000,"side":"Sell","size":73944},{"price":"8666.50","symbol":"BTCUSD","id":86665000,"side":"Sell","size":67528},{"price":"8667.00","symbol":"BTCUSD","id":86670000,"side":"Sell","size":108996},{"price":"8667.50","symbol":"BTCUSD","id":86675000,"side":"Sell","size":60727},{"price":"8668.00","symbol":"BTCUSD","id":86680000,"side":"Sell","size":88998},{"price":"8668.50","symbol":"BTCUSD","id":86685000,"side":"Sell","size":77975},{"price":"8669.00","symbol":"BTCUSD","id":86690000,"side":"Sell","size":58851},{"price":"8669.50","symbol":"BTCUSD","id":86695000,"side":"Sell","size":67649},{"price":"8670.00","symbol":"BTCUSD","id":86700000,"side":"Sell","size":215037},{"price":"8670.50","symbol":"BTCUSD","id":86705000,"side":"Sell","size":50038},{"price":"8671.00","symbol":"BTCUSD","id":86710000,"side":"Sell","size":109051}]},{"type":"delta","data":{"delete":[],"update":[{"price":"8658.00","symbol":"BTCUSD","id":86580000,"side":"Buy","size":399971}],"insert":[]},"cross_seq":1208104023,"ts":"2020-03-02T06:00:00.034Z"},{"type":"delta","data":{"delete":[],"update":[{"price":"8667.50","symbol":"BTCUSD","id":86675000,"side":"Sell","size":97163}],"insert":[]},"cross_seq":1208104024,"ts":"2020-03-02T06:00:00.117Z"},{"type":"delta","data":{"delete":[],"update":[{"price":"8668.50","symbol":"BTCUSD","id":86685000,"side":"Sell","size":119948}],"insert":[]},"cross_seq":1208104025,"ts":"2020-03-02T06:00:00.174Z"},{"type":"delta","data":{"delete":[],"update":[{"price":"8659.00","symbol":"BTCUSD","id":86590000,"side":"Sell","size":356188}],"insert":[]},"cross_seq":1208104026,"ts":"2020-03-02T06:00:00.199Z"},{"type":"delta","data":{"delete":[],"update":[{"price":"8658.50","symbol":"BTCUSD","id":86585000,"side":"Buy","size":403922}],"insert":[]},"cross_seq":1208104027,"ts":"2020-03-02T06:00:00.236Z"},{"type":"delta","data":{"delete":[],"update":[{"price":"8669.50","symbol":"BTCUSD","id":86695000,"side":"Sell","size":104627}],"insert":[]},"cross_seq":1208104029,"ts":"2020-03-02T06:00:00.335Z"},{"type":"delta","data":{"delete":[],"update":[{"price":"8662.00","symbol":"BTCUSD","id":86620000,"side":"Sell","size":328724},{"price":"8661.00","symbol":"BTCUSD","id":86610000,"side":"Sell","size":366494},{"price":"8666.00","symbol":"BTCUSD","id":86660000,"side":"Sell","size":23942},{"price":"8664.00","symbol":"BTCUSD","id":86640000,"side":"Sell","size":159912},{"price":"8663.00","symbol":"BTCUSD","id":86630000,"side":"Sell","size":85811},{"price":"8664.50","symbol":"BTCUSD","id":86645000,"side":"Sell","size":123209},{"price":"8667.00","symbol":"BTCUSD","id":86670000,"side":"Sell","size":78996}],"insert":[]},"cross_seq":1208104035,"ts":"2020-03-02T06:00:00.414Z"},{"type":"delta","data":{"delete":[],"update":[{"price":"8659.00","symbol":"BTCUSD","id":86590000,"side":"Sell","size":358167}],"insert":[]},"cross_seq":1208104036,"ts":"2020-03-02T06:00:00.436Z"},{"type":"delta","data":{"delete":[],"update":[{"price":"8659.00","symbol":"BTCUSD","id":86590000,"side":"Sell","size":358399}],"insert":[]},"cross_seq":1208104037,"ts":"2020-03-02T06:00:00.476Z"},{"type":"delta","data":{"delete":[],"update":[{"price":"8659.00","symbol":"BTCUSD","id":86590000,"side":"Sell","size":371802}],"insert":[]},"cross_seq":1208104041,"ts":"2020-03-02T06:00:00.759Z"},{"type":"delta","data":{"delete":[],"update":[{"price":"8668.00","symbol":"BTCUSD","id":86680000,"side":"Sell","size":127263}],"insert":[]},"cross_seq":1208104042,"ts":"2020-03-02T06:00:00.775Z"},{"type":"delta","data":{"delete":[],"update":[{"price":"8653.50","symbol":"BTCUSD","id":86535000,"side":"Buy","size":21735}],"insert":[]},"cross_seq":1208104043,"ts":"2020-03-02T06:00:00.877Z"},{"type":"delta","data":{"delete":[],"update":[{"price":"8652.50","symbol":"BTCUSD","id":86525000,"side":"Buy","size":178691}],"insert":[]},"cross_seq":1208104044,"ts":"2020-03-02T06:00:00.893Z"},{"type":"delta","data":{"delete":[],"update":[{"price":"8652.50","symbol":"BTCUSD","id":86525000,"side":"Buy","size":178702}],"insert":[]},"cross_seq":1208104045,"ts":"2020-03-02T06:00:00.917Z"},{"type":"delta","data":{"delete":[],"update":[{"price":"8668.00","symbol":"BTCUSD","id":86680000,"side":"Sell","size":127438}],"insert":[]},"cross_seq":1208104047,"ts":"2020-03-02T06:00:00.934Z"},{"type":"delta","data":{"delete":[],"update":[{"price":"8668.50","symbol":"BTCUSD","id":86685000,"side":"Sell","size":119958},{"price":"8667.50","symbol":"BTCUSD","id":86675000,"side":"Sell","size":96132}],"insert":[]},"cross_seq":1208104049,"ts":"2020-03-02T06:00:00.957Z"},{"type":"delta","data":{"delete":[],"update":[{"price":"8660.50","symbol":"BTCUSD","id":86605000,"side":"Sell","size":319014}],"insert":[]},"cross_seq":1208104050,"ts":"2020-03-02T06:00:00.978Z"},{"type":"delta","data":{"delete":[],"update":[{"price":"8653.50","symbol":"BTCUSD","id":86535000,"side":"Buy","size":16735}],"insert":[]},"cross_seq":1208104051,"ts":"2020-03-02T06:00:01.036Z"},{"type":"delta","data":{"delete":[],"update":[{"price":"8657.00","symbol":"BTCUSD","id":86570000,"side":"Buy","size":256554}],"insert":[]},"cross_seq":1208104052,"ts":"2020-03-02T06:00:01.075Z"},{"type":"delta","data":{"delete":[],"update":[{"price":"8660.50","symbol":"BTCUSD","id":86605000,"side":"Sell","size":276161},{"price":"8657.50","symbol":"BTCUSD","id":86575000,"side":"Buy","size":373652},{"price":"8656.50","symbol":"BTCUSD","id":86565000,"side":"Buy","size":184858},{"price":"8657.00","symbol":"BTCUSD","id":86570000,"side":"Buy","size":336550},{"price":"8661.50","symbol":"BTCUSD","id":86615000,"side":"Sell","size":176696}],"insert":[]},"cross_seq":1208104057,"ts":"2020-03-02T06:00:01.115Z"},{"type":"delta","data":{"delete":[],"update":[{"price":"8659.00"
